# pi-DriveUp failed to authenticate with OneDrive.
### How do I solve this?
Manually run `backup.py`. Find the error. If you need help, [make an issue](https://github.com/KTibow/pi-DriveUp/issues/new).   
### What does the error look like?
Something like:
```
Couldn't authenticate with OneDrive because of [the error].
```
### Why did this happen?
There are multiple possible reasons. A likely one is that you weren't connected to the Internet. If you can't fix it, [make an issue](https://github.com/KTibow/pi-DriveUp/issues/new).
