# pi-DriveUp failed to load.
### How do I solve this?
Manually run `backup.py`. Find the error. If you need help, [make an issue](https://github.com/KTibow/pi-DriveUp/issues/new).   
### What does the error look like?
Something like:
```
Couldn't load because of [the error].
```
